<?xml version="1.0"?>
<robot xmlns:xacro="http://www.ros.org/wiki/xacro" >

    <!-- =================================================================================== -->
    <!-- |    This XACRO contains physical elements (the chassis and wheels ) of the robot | -->
    <!-- =================================================================================== -->
    
    <xacro:include filename="/home/enrique/catkin_ws/src/algorithm/models/robot/materials.xacro" />
    <xacro:include filename="/home/enrique/catkin_ws/src/algorithm/models/robot/inertial_macros.xacro" />
    <xacro:include filename="/home/enrique/catkin_ws/src/algorithm/models/robot/sensors.xacro" />

    <!--BASE LINK-->

    <link name="base_link">

    </link>

    <!--CHASSIS LINK-->

    <joint name="chassis_joint" type="fixed">
        <parent link="base_link" />
        <child link="chassis" />
        <!--Origin of the joint-->
        <origin xyz="-0.1 0 0" />
    </joint>    

    <link name="chassis">
        <visual>
            <!-- Origin of the box -->
            <origin xyz="0.15 0 0.075" />
            <geometry>
                <!--Geometry of the chassis (0.3(x dimension in meters), 0.3(y dimension in meters), 0.15 (z dimension in meters))-->
                <box size="0.3 0.3 0.15" />
            </geometry>
            <!--Material-->
            <xacro:blue_material />            
        </visual>
        <collision name="chassis_link_bump_sensor_collision">
            <!-- Origin of the box -->
            <origin xyz="0.15 0 0.075" />
            <geometry>
                <!--Geometry of the chassis (0.3(x dimension in meters), 0.3(y dimension in meters), 0.15 (z dimension in meters))-->
                <box size="0.3 0.3 0.15" />
            </geometry>            
        </collision>
        <xacro:inertial_box mass="0.5" x="0.3" y="0.3" z="0.15">
            <origin xyz="0.15 0 0.075" rpy="0 0 0" />
        </xacro:inertial_box>        
    </link>

    <xacro:blue_gazebo_material object="chassis" />

    <!-- LEFT WHEEL JOINT-->
    
    <joint name="left_wheel_joint" type="continuous">
        <parent link="base_link" />
        <child link="left_wheel" />      
        <origin xyz="0 0.175 0" rpy ="-${pi/2} 0 0" />
        <axis xyz="0 0 1" />
    </joint>

    <link name="left_wheel">
        <visual>
            <geometry>
                <cylinder radius="0.05" length="0.04" />
            </geometry>
            <xacro:blue_material />
        </visual>
        <collision name="left_wheel_link_bump_sensor_collision">
            <geometry>
                <cylinder radius="0.05" length="0.04" />
            </geometry>            
        </collision>
        <xacro:inertial_cylinder mass="0.1" length="0.04" radius="0.05">
            <origin xyz="0 0 0" rpy="0 0 0"/>
        </xacro:inertial_cylinder>
    </link>

    <xacro:blue_gazebo_material object="left_wheel" />

    <!-- RIGHT WHEEL JOINT-->
    
    <joint name="right_wheel_joint" type="continuous">
        <parent link="base_link" />
        <child link="right_wheel" />      
        <origin xyz="0 -0.175 0" rpy ="${pi/2} 0 0" />
        <axis xyz="0 0 -1" />
    </joint>

    <link name="right_wheel">
        <visual>
            <geometry>
                <cylinder radius="0.05" length="0.04" />
            </geometry>
            <xacro:blue_material />
        </visual>
        <collision name="right_wheel_link_bump_sensor_collision">
            <geometry>
                <cylinder radius="0.05" length="0.04" />
            </geometry>            
        </collision>
        <xacro:inertial_cylinder mass="0.1" length="0.04" radius="0.05">
            <origin xyz="0 0 0" rpy="0 0 0"/>
        </xacro:inertial_cylinder>
    </link>

    <xacro:blue_gazebo_material object="right_wheel" />

    <!-- CASTER WHEEL LINK -->

    <joint name="caster_wheel_joint" type="fixed">
        <parent link="chassis" />
        <child link="caster_wheel" />
        <origin xyz="0.24 0 0" />
    </joint>

    <link name="caster_wheel">
        <visual>
            <geometry>
                <sphere radius="0.05" />
            </geometry>
            <xacro:black_material />            
        </visual>
        <collision>
            <geometry>
                <sphere radius="0.05" />
            </geometry>            
        </collision>
        <xacro:inertial_sphere mass="0.1" radius="0.05">
            <origin xyz="0 0 0" rpy="0 0 0"/>
        </xacro:inertial_sphere>
    </link>

    <xacro:black_gazebo_material object="caster_wheel" />
    <gazebo reference="caster_wheel">
        <!-- Reduce the friction of the caster wheel with the enviroment -->
        <mu1 value="0.001" />
        <mu2 value="0.001" />
    </gazebo>




</robot>